2021-05-16 13:41:12,782 ERROR: Exception on /auth/login [GET] [in c:\users\justin\desktop\gitprojects\mypr\venv\lib\site-packages\flask\app.py:1441]
Traceback (most recent call last):
  File "c:\users\justin\desktop\gitprojects\mypr\venv\lib\site-packages\flask\app.py", line 2051, in wsgi_app
    response = self.full_dispatch_request()
  File "c:\users\justin\desktop\gitprojects\mypr\venv\lib\site-packages\flask\app.py", line 1501, in full_dispatch_request
    rv = self.handle_user_exception(e)
  File "c:\users\justin\desktop\gitprojects\mypr\venv\lib\site-packages\flask\app.py", line 1499, in full_dispatch_request
    rv = self.dispatch_request()
  File "c:\users\justin\desktop\gitprojects\mypr\venv\lib\site-packages\flask\app.py", line 1485, in dispatch_request
    return self.ensure_sync(self.view_functions[rule.endpoint])(**req.view_args)
  File "C:\Users\Justin\Desktop\gitProjects\MyPR\app\auth\routes.py", line 27, in login
    return render_template('auth/login.html', title='Sign In', form=form)
  File "c:\users\justin\desktop\gitprojects\mypr\venv\lib\site-packages\flask\templating.py", line 150, in render_template
    ctx.app,
  File "c:\users\justin\desktop\gitprojects\mypr\venv\lib\site-packages\flask\templating.py", line 128, in _render
    rv = template.render(context)
  File "c:\users\justin\desktop\gitprojects\mypr\venv\lib\site-packages\jinja2\environment.py", line 1289, in render
    self.environment.handle_exception()
  File "c:\users\justin\desktop\gitprojects\mypr\venv\lib\site-packages\jinja2\environment.py", line 924, in handle_exception
    raise rewrite_traceback_stack(source=source)
  File "C:\Users\Justin\Desktop\gitProjects\MyPR\app\templates\auth\login.html", line 1, in top-level template code
    {% extends "base.html" %}
  File "C:\Users\Justin\Desktop\gitProjects\MyPR\app\templates\base.html", line 1, in top-level template code
    {% extends 'bootstrap/base.html' %}
  File "c:\users\justin\desktop\gitprojects\mypr\venv\lib\site-packages\flask_bootstrap\templates\bootstrap\base.html", line 1, in top-level template code
    {% block doc -%}
  File "c:\users\justin\desktop\gitprojects\mypr\venv\lib\site-packages\flask_bootstrap\templates\bootstrap\base.html", line 4, in block 'doc'
    {%- block html %}
  File "c:\users\justin\desktop\gitprojects\mypr\venv\lib\site-packages\flask_bootstrap\templates\bootstrap\base.html", line 20, in block 'html'
    {% block body -%}
  File "c:\users\justin\desktop\gitprojects\mypr\venv\lib\site-packages\flask_bootstrap\templates\bootstrap\base.html", line 23, in block 'body'
    {% block content -%}
  File "C:\Users\Justin\Desktop\gitProjects\MyPR\app\templates\auth\login.html", line 8, in block 'content'
    {{ form.username.label }}<br>
  File "c:\users\justin\desktop\gitprojects\mypr\venv\lib\site-packages\wtforms\fields\core.py", line 416, in __html__
    return self()
  File "c:\users\justin\desktop\gitprojects\mypr\venv\lib\site-packages\wtforms\fields\core.py", line 425, in __call__
    text = escape(text or self.text)
  File "c:\users\justin\desktop\gitprojects\mypr\venv\lib\site-packages\flask_babel\speaklater.py", line 66, in __html__
    return str(self)
  File "c:\users\justin\desktop\gitprojects\mypr\venv\lib\site-packages\flask_babel\speaklater.py", line 21, in __str__
    return str(self._func(*self._args, **self._kwargs))
  File "c:\users\justin\desktop\gitprojects\mypr\venv\lib\site-packages\flask_babel\__init__.py", line 689, in gettext
    return get_domain().gettext(*args, **kwargs)
  File "c:\users\justin\desktop\gitprojects\mypr\venv\lib\site-packages\flask_babel\__init__.py", line 682, in get_domain
    babel = current_app.extensions['babel']
KeyError: 'babel'
2021-05-16 13:43:54,365 INFO: MyPR startup [in C:\Users\Justin\Desktop\gitProjects\MyPR\app\__init__.py:88]
2021-05-16 13:43:56,241 ERROR: Exception on /auth/login [GET] [in c:\users\justin\desktop\gitprojects\mypr\venv\lib\site-packages\flask\app.py:1441]
Traceback (most recent call last):
  File "c:\users\justin\desktop\gitprojects\mypr\venv\lib\site-packages\flask\app.py", line 2051, in wsgi_app
    response = self.full_dispatch_request()
  File "c:\users\justin\desktop\gitprojects\mypr\venv\lib\site-packages\flask\app.py", line 1501, in full_dispatch_request
    rv = self.handle_user_exception(e)
  File "c:\users\justin\desktop\gitprojects\mypr\venv\lib\site-packages\flask\app.py", line 1499, in full_dispatch_request
    rv = self.dispatch_request()
  File "c:\users\justin\desktop\gitprojects\mypr\venv\lib\site-packages\flask\app.py", line 1485, in dispatch_request
    return self.ensure_sync(self.view_functions[rule.endpoint])(**req.view_args)
  File "C:\Users\Justin\Desktop\gitProjects\MyPR\app\auth\routes.py", line 27, in login
    return render_template('auth/login.html', title='Sign In', form=form)
  File "c:\users\justin\desktop\gitprojects\mypr\venv\lib\site-packages\flask\templating.py", line 150, in render_template
    ctx.app,
  File "c:\users\justin\desktop\gitprojects\mypr\venv\lib\site-packages\flask\templating.py", line 128, in _render
    rv = template.render(context)
  File "c:\users\justin\desktop\gitprojects\mypr\venv\lib\site-packages\jinja2\environment.py", line 1289, in render
    self.environment.handle_exception()
  File "c:\users\justin\desktop\gitprojects\mypr\venv\lib\site-packages\jinja2\environment.py", line 924, in handle_exception
    raise rewrite_traceback_stack(source=source)
  File "C:\Users\Justin\Desktop\gitProjects\MyPR\app\templates\auth\login.html", line 1, in top-level template code
    {% extends "base.html" %}
  File "C:\Users\Justin\Desktop\gitProjects\MyPR\app\templates\base.html", line 1, in top-level template code
    {% extends 'bootstrap/base.html' %}
  File "c:\users\justin\desktop\gitprojects\mypr\venv\lib\site-packages\flask_bootstrap\templates\bootstrap\base.html", line 1, in top-level template code
    {% block doc -%}
  File "c:\users\justin\desktop\gitprojects\mypr\venv\lib\site-packages\flask_bootstrap\templates\bootstrap\base.html", line 4, in block 'doc'
    {%- block html %}
  File "c:\users\justin\desktop\gitprojects\mypr\venv\lib\site-packages\flask_bootstrap\templates\bootstrap\base.html", line 20, in block 'html'
    {% block body -%}
  File "c:\users\justin\desktop\gitprojects\mypr\venv\lib\site-packages\flask_bootstrap\templates\bootstrap\base.html", line 23, in block 'body'
    {% block content -%}
  File "C:\Users\Justin\Desktop\gitProjects\MyPR\app\templates\auth\login.html", line 24, in block 'content'
    <p>New User? <a href="{{ url_for('register') }}">Click to Register!</a></p>
  File "c:\users\justin\desktop\gitprojects\mypr\venv\lib\site-packages\flask\helpers.py", line 334, in url_for
    return appctx.app.handle_url_build_error(error, endpoint, values)
  File "c:\users\justin\desktop\gitprojects\mypr\venv\lib\site-packages\flask\helpers.py", line 322, in url_for
    endpoint, values, method=method, force_external=external
  File "c:\users\justin\desktop\gitprojects\mypr\venv\lib\site-packages\werkzeug\routing.py", line 2301, in build
    raise BuildError(endpoint, values, method, self)
werkzeug.routing.BuildError: Could not build url for endpoint 'register'. Did you mean 'auth.register' instead?
2021-05-16 13:44:14,550 INFO: MyPR startup [in C:\Users\Justin\Desktop\gitProjects\MyPR\app\__init__.py:88]
2021-05-16 13:44:48,578 ERROR: Exception on /unfollow/cow [POST] [in c:\users\justin\desktop\gitprojects\mypr\venv\lib\site-packages\flask\app.py:1441]
Traceback (most recent call last):
  File "c:\users\justin\desktop\gitprojects\mypr\venv\lib\site-packages\flask\app.py", line 2051, in wsgi_app
    response = self.full_dispatch_request()
  File "c:\users\justin\desktop\gitprojects\mypr\venv\lib\site-packages\flask\app.py", line 1501, in full_dispatch_request
    rv = self.handle_user_exception(e)
  File "c:\users\justin\desktop\gitprojects\mypr\venv\lib\site-packages\flask\app.py", line 1499, in full_dispatch_request
    rv = self.dispatch_request()
  File "c:\users\justin\desktop\gitprojects\mypr\venv\lib\site-packages\flask\app.py", line 1485, in dispatch_request
    return self.ensure_sync(self.view_functions[rule.endpoint])(**req.view_args)
  File "c:\users\justin\desktop\gitprojects\mypr\venv\lib\site-packages\flask_login\utils.py", line 272, in decorated_view
    return func(*args, **kwargs)
  File "C:\Users\Justin\Desktop\gitProjects\MyPR\app\main\routes.py", line 122, in unfollow
    flash('You are not following %(username)s.', username=username)
TypeError: flash() got an unexpected keyword argument 'username'
2021-05-16 13:47:36,094 INFO: MyPR startup [in C:\Users\Justin\Desktop\gitProjects\MyPR\app\__init__.py:88]
